Workbook

Sheet Read Me
A1: Rewards Microfrontend: HLRD and LLRD workbook
A2: Generated 2026-09-29 from docs/rewards/HLRD.md and docs/rewards/LLRD.md.
A4: How to use this workbook
A5: • Requirements Register: one row per requirement. Edit the yellow columns (Requirement, Status, Priority, Owner, Success measure, Notes). Status and Priority are dropdowns.
A6: • To add a requirement, add a row at the bottom of the register: give it an ID (e.g. LLR-4.19) and a Parent epic (e.g. HLR-9); the Traceability tab counts it automatically.
A7: • Traceability: live formulas per epic (how many requirements, how many built). Don't type over it.
A8: • HLRD / LLRD tabs: each section of the documents with its tables, for reading and light edits.
A9: • The markdown files remain the source of truth. After editing here, ask Claude to sync your changes back into the markdown (and Miro).
A11: Status values
A12: Built & tested: implemented with automated tests
A13: Built (manual test): implemented, verified by hand in the browser
A14: Next: agreed and scheduled next (e.g. HLR-9 reward scope, migrations)
... A19: LLR-4.19 | Functional (LLR) | HLR-9 | Reward cards show how many days are left to keep a streak reward alive | Next | Should | Mansi

Sheet Requirements Register
A1: Requirements Register
A2: One row per requirement. Yellow columns are yours to edit; Status and Priority have dropdowns.
A4: ID | B4: Type | C4: Parent epic | D4: Requirement | E4: Status | F4: Priority | G4: Owner | H4: Success measure / acceptance | I4: Notes | J4: Source
A5: BR-1 | B5: Business requirement | D5: Make recurring upkeep visible and motivating | F5: Should | G5: Mansi | H5: ≥ 3 active streaks maintained for 2 weeks in personal use | J5: HLRD › 6. High-level requirements
A6: BR-2 | B6: Business requirement | D6: Reduce effort to decide what to do in an area | F6: Should | G6: Mansi | H6: Post-MVP: ≥ 50 % of AI suggestions marked Relevant | J6: HLRD › 6. High-level requirements
A7: BR-3 | B7: Business requirement | D7: Provide weekly insight into effort distribution | F7: Should | G7: Mansi | H7: Weekly review done from the dashboard in < 2 min | J7: HLRD › 6. High-level requirements
A8: BR-4 | B8: Business requirement | D8: Demonstrate MFE, BFF, integration and data-app principles (capstone) | F8: Should | G8: Mansi | H8: 3-minute demo script runs end to end | J8: HLRD › 6. High-level requirements
A9: BR-5 | B9: Business requirement | D9: Be ready for an Android client without backend rewrite | F9: Should | G9: Mansi | H9: All user actions available via documented API (OpenAPI) | J9: HLRD › 6. High-level requirements
A10: HLR-1 | B10: Epic (HLR) | D10: Tiles & areas: User-managed tiles and areas (create, edit, reorder, delete); empty start with an optional starter set | E10: Next | F10: Must | G10: Mansi | J10: HLRD › 6. High-level requirements
A11: HLR-2 | B11: Epic (HLR) | D11: Task management: Create, prioritise, filter, change status/frequency/relevance | E11: Built & tested | F11: Must | G11: Mansi | J11: HLRD › 6. High-level requirements
A12: HLR-3 | B12: Epic (HLR) | D12: Completion & streaks: Log completions with note/backfill; activity log; current/best streak | E12: Built & tested | F12: Must | G12: Mansi | J12: HLRD › 6. High-level requirements
A13: HLR-4 | B13: Epic (HLR) | D13: Rewards: Create, tag, progress, auto-unlock, claim | E13: Built & tested | F13: Must | G13: Mansi | J13: HLRD › 6. High-level requirements
A14: HLR-5 | B14: Epic (HLR) | D14: Insights dashboard: Aggregates, filters, cached reads, claim from dashboard | E14: Built & tested | F14: Must | G14: Mansi | J14: HLRD › 6. High-level requirements
A15: HLR-6 | B15: Epic (HLR) | D15: AI task suggestions: Photos → suggestions → decisions → tasks; non-blocking | E15: Planned | F15: Should | G15: Mansi | J15: HLRD › 6. High-level requirements
A16: HLR-7 | B16: Epic (HLR) | D16: Module composition: Independently delivered MFE with host fallback | E16: Built & tested | F16: Must | G16: Mansi | J16: HLRD › 6. High-level requirements
A17: HLR-8 | B17: Epic (HLR) | D17: API (BFF): Versionable, documented, client-shaped API with demo auth | E17: Built & tested | F17: Must | G17: Mansi | J17: HLRD › 6. High-level requirements
A18: HLR-9 | B18: Epic (HLR) | D18: Reward scope and matching: Rewards live in the same tiles and areas as tasks; tasks are matched to rewards inside that scope (selected tasks, or all tasks in scope); existing rewards migrated without data loss | E18: Next | F18: Must | G18: Mansi | J18: HLRD › 6. High-level requirements
A19: HLR-10 | B19: Epic (HLR) | D19: Notes, contacts and files: Every tile and area holds notes, contacts (customer care, service executives, vendors) and files (bills, warranty cards), grouped by topic such as "Bosch Dishwasher", with tap-to-call and search | E19: Next | F19: Must | G19: Mansi | J19: HLRD › 6. High-level requirements
A20: HLR-11 | B20: Epic (HLR) | D20: Task planning and visibility: Tasks can be milestones (badge, filter, "milestone completed" reward rule, bigger celebration), have a due date and time and a days-to-complete target, and be announced or silent (silent = hidden from the public view and completed without celebration) | E20: Next | F20: Must | G20: Mansi | J20: HLRD › 6. High-level requirements
A21: HLR-12 | B21: Epic (HLR) | D21: Reward ideas and wishlist: Capture a reward idea in seconds (e.g. a book for Shiragi spotted at the library) without a rule; turn it into a real reward later, or mark it bought or dropped; every reward says who it's for | E21: Next | F21: Must | G21: Mansi | J21: HLRD › 6. High-level requirements
A22: HNFR-1 | B22: Non-functional (high level) | C22: Cross-cutting | D22: Usability: Mobile-first; every primary action reachable in ≤ 3 taps from the area screen | E22: Built (manual test) | F22: Must | G22: Mansi | J22: HLRD › 6. High-level requirements
A23: HNFR-2 | B23: Non-functional (high level) | C23: Cross-cutting | D23: Resilience: No single dependency failure (remote, BFF, AI) blanks the host page | E23: Built (manual test) | F23: Must | G23: Mansi | J23: HLRD › 6. High-level requirements
A24: HNFR-3 | B24: Non-functional (high level) | C24: Cross-cutting | D24: Performance: Rewards screen interactive ≤ 2 s on local/broadband; dashboard cached reads | E24: Built (manual test) | F24: Must | G24: Mansi | J24: HLRD › 6. High-level requirements
A25: HNFR-4 | B25: Non-functional (high level) | C25: Cross-cutting | D25: Security: Secrets server-side only; CORS allow-list; private photo storage | E25: Built (manual test) | F25: Must | G25: Mansi | J25: HLRD › 6. High-level requirements
A26: HNFR-5 | B26: Non-functional (high level) | C26: Cross-cutting | D26: Accessibility: WCAG 2.2 AA intent: labels, focus, live regions, contrast, reduced motion | E26: Built (manual test) | F26: Must | G26: Mansi | J26: HLRD › 6. High-level requirements
A27: HNFR-6 | B27: Non-functional (high level) | C27: Cross-cutting | D27: Maintainability: Typed contracts; pure, unit-tested business rules; ≥ 1 test per business rule | E27: Built (manual test) | F27: Must | G27: Mansi | J27: HLRD › 6. High-level requirements
A28: HNFR-7 | B28: Non-functional (high level) | C28: Cross-cutting | D28: Portability: HTTP/JSON only between tiers; storage swappable (SQLite → Postgres) | E28: Built (manual test) | F28: Must | G28: Mansi | J28: HLRD › 6. High-level requirements
A29: LLR-1.1 | B29: Functional (LLR) | C29: HLR-1 | D29: Superseded by LLR-1.7 (Q15). Was: on first start the system seeds tiles and areas per Q2 | E29: Out of scope | F29: Should | G29: Mansi | J29: LLRD › 3. Detailed functional requirements
A30: LLR-1.2 | B30: Functional (LLR) | C30: HLR-1 | D30: The tiles screen shows each tile's icon, name, area count and active task count | E30: Built (manual test) | F30: Must | G30: Mansi | J30: LLRD › 3. Detailed functional requirements
A31: LLR-1.3 | B31: Functional (LLR) | C31: HLR-1 | D31: The user can add an area to a tile. The name is 1–80 characters, trimmed, and unique within the tile ignoring case | E31: Built & tested | F31: Must | G31: Mansi | J31: LLRD › 3. Detailed functional requirements
A32: LLR-1.4 | B32: Functional (LLR) | C32: HLR-1 | D32: The user can rename an area under the same rules as LLR-1.3 | E32: Built & tested | F32: Must | G32: Mansi | J32: LLRD › 3. Detailed functional requirements
A33: LLR-1.5 | B33: Functional (LLR) | C33: HLR-1 | D33: The user can delete an area after confirmation. Its tasks, completions, photos and suggestions are removed with it | E33: Built & tested | F33: Must | G33: Mansi | J33: LLRD › 3. Detailed functional requirements
... A192: NFR-D11 | B192: Non-functional (detailed) | C192: Cross-cutting | D192: Every read endpoint has a test that a silent task leaves no trace (item, count or aggregate) in its response without the passcode | E192: Next | F192: Must | G192: Mansi | J192: LLRD › 6. Detailed non-functional requirements

Sheet Traceability
A1: Traceability by epic
A2: Counts are live formulas over the Requirements Register; change a status there and this updates.
A4: Epic | B4: Title | C4: LLRs + rules | D4: Built & tested | E4: Built (manual) | F4: Next | G4: Planned | H4: % built
A5: HLR-1 | B5: =IFERROR(INDEX('Requirements Register'!$D$5:$D$392,MATCH(A5,'Requirements Register'!$A$5:$A$392,0)),"") -> Tiles & areas: User-managed tiles and areas (create, edit, reorder, delete); empty start with an optional starter set | C5: =COUNTIF('Requirements Register'!$C$5:$C$392,A5) -> 17 | D5: =COUNTIFS('Requirements Register'!$C$5:$C$392,A5,'Requirements Register'!$E$5:$E$392,"Built & tested") -> 3 | E5: =COUNTIFS('Requirements Register'!$C$5:$C$392,A5,'Requirements Register'!$E$5:$E$392,"Built (manual test)") -> 2 | F5: =COUNTIFS('Requirements Register'!$C$5:$C$392,A5,'Requirements Register'!$E$5:$E$392,"Next") -> 11 | G5: =COUNTIFS('Requirements Register'!$C$5:$C$392,A5,'Requirements Register'!$E$5:$E$392,"Planned") -> 0 | H5: =IF(C5=0,"-",(D5+E5)/C5) -> 0.29411765
A6: HLR-2 | B6: =IFERROR(INDEX('Requirements Register'!$D$5:$D$392,MATCH(A6,'Requirements Register'!$A$5:$A$392,0)),"") -> Task management: Create, prioritise, filter, change status/frequency/relevance | C6: =COUNTIF('Requirements Register'!$C$5:$C$392,A6) -> 9 | D6: =COUNTIFS('Requirements Register'!$C$5:$C$392,A6,'Requirements Register'!$E$5:$E$392,"Built & tested") -> 7 | E6: =COUNTIFS('Requirements Register'!$C$5:$C$392,A6,'Requirements Register'!$E$5:$E$392,"Built (manual test)") -> 2 | F6: =COUNTIFS('Requirements Register'!$C$5:$C$392,A6,'Requirements Register'!$E$5:$E$392,"Next") -> 0 | G6: =COUNTIFS('Requirements Register'!$C$5:$C$392,A6,'Requirements Register'!$E$5:$E$392,"Planned") -> 0 | H6: =IF(C6=0,"-",(D6+E6)/C6) -> 1
A7: HLR-3 | B7: =IFERROR(INDEX('Requirements Register'!$D$5:$D$392,MATCH(A7,'Requirements Register'!$A$5:$A$392,0)),"") -> Completion & streaks: Log completions with note/backfill; activity log; current/best streak | C7: =COUNTIF('Requirements Register'!$C$5:$C$392,A7) -> 14 | D7: =COUNTIFS('Requirements Register'!$C$5:$C$392,A7,'Requirements Register'!$E$5:$E$392,"Built & tested") -> 12 | E7: =COUNTIFS('Requirements Register'!$C$5:$C$392,A7,'Requirements Register'!$E$5:$E$392,"Built (manual test)") -> 2 | F7: =COUNTIFS('Requirements Register'!$C$5:$C$392,A7,'Requirements Register'!$E$5:$E$392,"Next") -> 0 | G7: =COUNTIFS('Requirements Register'!$C$5:$C$392,A7,'Requirements Register'!$E$5:$E$392,"Planned") -> 0 | H7: =IF(C7=0,"-",(D7+E7)/C7) -> 1
A8: HLR-4 | B8: =IFERROR(INDEX('Requirements Register'!$D$5:$D$392,MATCH(A8,'Requirements Register'!$A$5:$A$392,0)),"") -> Rewards: Create, tag, progress, auto-unlock, claim | C8: =COUNTIF('Requirements Register'!$C$5:$C$392,A8) -> 13 | D8: =COUNTIFS('Requirements Register'!$C$5:$C$392,A8,'Requirements Register'!$E$5:$E$392,"Built & tested") -> 11 | E8: =COUNTIFS('Requirements Register'!$C$5:$C$392,A8,'Requirements Register'!$E$5:$E$392,"Built (manual test)") -> 2 | F8: =COUNTIFS('Requirements Register'!$C$5:$C$392,A8,'Requirements Register'!$E$5:$E$392,"Next") -> 0 | G8: =COUNTIFS('Requirements Register'!$C$5:$C$392,A8,'Requirements Register'!$E$5:$E$392,"Planned") -> 0 | H8: =IF(C8=0,"-",(D8+E8)/C8) -> 1
A9: HLR-5 | B9: =IFERROR(INDEX('Requirements Register'!$D$5:$D$392,MATCH(A9,'Requirements Register'!$A$5:$A$392,0)),"") -> Insights dashboard: Aggregates, filters, cached reads, claim from dashboard | C9: =COUNTIF('Requirements Register'!$C$5:$C$392,A9) -> 11 | D9: =COUNTIFS('Requirements Register'!$C$5:$C$392,A9,'Requirements Register'!$E$5:$E$392,"Built & tested") -> 3 | E9: =COUNTIFS('Requirements Register'!$C$5:$C$392,A9,'Requirements Register'!$E$5:$E$392,"Built (manual test)") -> 7 | F9: =COUNTIFS('Requirements Register'!$C$5:$C$392,A9,'Requirements Register'!$E$5:$E$392,"Next") -> 1 | G9: =COUNTIFS('Requirements Register'!$C$5:$C$392,A9,'Requirements Register'!$E$5:$E$392,"Planned") -> 0 | H9: =IF(C9=0,"-",(D9+E9)/C9) -> 0.90909091
A10: HLR-6 | B10: =IFERROR(INDEX('Requirements Register'!$D$5:$D$392,MATCH(A10,'Requirements Register'!$A$5:$A$392,0)),"") -> AI task suggestions: Photos → suggestions → decisions → tasks; non-blocking | C10: =COUNTIF('Requirements Register'!$C$5:$C$392,A10) -> 9 | D10: =COUNTIFS('Requirements Register'!$C$5:$C$392,A10,'Requirements Register'!$E$5:$E$392,"Built & tested") -> 0 | E10: =COUNTIFS('Requirements Register'!$C$5:$C$392,A10,'Requirements Register'!$E$5:$E$392,"Built (manual test)") -> 0 | F10: =COUNTIFS('Requirements Register'!$C$5:$C$392,A10,'Requirements Register'!$E$5:$E$392,"Next") -> 0 | G10: =COUNTIFS('Requirements Register'!$C$5:$C$392,A10,'Requirements Register'!$E$5:$E$392,"Planned") -> 9 | H10: =IF(C10=0,"-",(D10+E10)/C10) -> 0
A11: HLR-7 | B11: =IFERROR(INDEX('Requirements Register'!$D$5:$D$392,MATCH(A11,'Requirements Register'!$A$5:$A$392,0)),"") -> Module composition: Independently delivered MFE with host fallback | C11: =COUNTIF('Requirements Register'!$C$5:$C$392,A11) -> 8 | D11: =COUNTIFS('Requirements Register'!$C$5:$C$392,A11,'Requirements Register'!$E$5:$E$392,"Built & tested") -> 2 | E11: =COUNTIFS('Requirements Register'!$C$5:$C$392,A11,'Requirements Register'!$E$5:$E$392,"Built (manual test)") -> 6 | F11: =COUNTIFS('Requirements Register'!$C$5:$C$392,A11,'Requirements Register'!$E$5:$E$392,"Next") -> 0 | G11: =COUNTIFS('Requirements Register'!$C$5:$C$392,A11,'Requirements Register'!$E$5:$E$392,"Planned") -> 0 | H11: =IF(C11=0,"-",(D11+E11)/C11) -> 1
A12: HLR-8 | B12: =IFERROR(INDEX('Requirements Register'!$D$5:$D$392,MATCH(A12,'Requirements Register'!$A$5:$A$392,0)),"") -> API (BFF): Versionable, documented, client-shaped API with demo auth | C12: =COUNTIF('Requirements Register'!$C$5:$C$392,A12) -> 7 | D12: =COUNTIFS('Requirements Register'!$C$5:$C$392,A12,'Requirements Register'!$E$5:$E$392,"Built & tested") -> 7 | E12: =COUNTIFS('Requirements Register'!$C$5:$C$392,A12,'Requirements Register'!$E$5:$E$392,"Built (manual test)") -> 0 | F12: =COUNTIFS('Requirements Register'!$C$5:$C$392,A12,'Requirements Register'!$E$5:$E$392,"Next") -> 0 | G12: =COUNTIFS('Requirements Register'!$C$5:$C$392,A12,'Requirements Register'!$E$5:$E$392,"Planned") -> 0 | H12: =IF(C12=0,"-",(D12+E12)/C12) -> 1
A13: HLR-9 | B13: =IFERROR(INDEX('Requirements Register'!$D$5:$D$392,MATCH(A13,'Requirements Register'!$A$5:$A$392,0)),"") -> Reward scope and matching: Rewards live in the same tiles and areas as tasks; tasks are matched to rewards inside that scope (selected tasks, or all tasks in scope); existing rewards migrated without data loss | C13: =COUNTIF('Requirements Register'!$C$5:$C$392,A13) -> 17 | D13: =COUNTIFS('Requirements Register'!$C$5:$C$392,A13,'Requirements Register'!$E$5:$E$392,"Built & tested") -> 0 | E13: =COUNTIFS('Requirements Register'!$C$5:$C$392,A13,'Requirements Register'!$E$5:$E$392,"Built (manual test)") -> 0 | F13: =COUNTIFS('Requirements Register'!$C$5:$C$392,A13,'Requirements Register'!$E$5:$E$392,"Next") -> 17 | G13: =COUNTIFS('Requirements Register'!$C$5:$C$392,A13,'Requirements Register'!$E$5:$E$392,"Planned") -> 0 | H13: =IF(C13=0,"-",(D13+E13)/C13) -> 0
A14: HLR-10 | B14: =IFERROR(INDEX('Requirements Register'!$D$5:$D$392,MATCH(A14,'Requirements Register'!$A$5:$A$392,0)),"") -> Notes, contacts and files: Every tile and area holds notes, contacts (customer care, service executives, vendors) and files (bills, warranty cards), grouped by topic such as "Bosch Dishwasher", with tap-to-call and search | C14: =COUNTIF('Requirements Register'!$C$5:$C$392,A14) -> 15 | D14: =COUNTIFS('Requirements Register'!$C$5:$C$392,A14,'Requirements Register'!$E$5:$E$392,"Built & tested") -> 0 | E14: =COUNTIFS('Requirements Register'!$C$5:$C$392,A14,'Requirements Register'!$E$5:$E$392,"Built (manual test)") -> 0 | F14: =COUNTIFS('Requirements Register'!$C$5:$C$392,A14,'Requirements Register'!$E$5:$E$392,"Next") -> 15 | G14: =COUNTIFS('Requirements Register'!$C$5:$C$392,A14,'Requirements Register'!$E$5:$E$392,"Planned") -> 0 | H14: =IF(C14=0,"-",(D14+E14)/C14) -> 0
A15: HLR-11 | B15: =IFERROR(INDEX('Requirements Register'!$D$5:$D$392,MATCH(A15,'Requirements Register'!$A$5:$A$392,0)),"") -> Task planning and visibility: Tasks can be milestones (badge, filter, "milestone completed" reward rule, bigger celebration), have a due date and time and a days-to-complete target, and be announced or silent (silent = hidden from the public view and completed without celebration) | C15: =COUNTIF('Requirements Register'!$C$5:$C$392,A15) -> 19 | D15: =COUNTIFS('Requirements Register'!$C$5:$C$392,A15,'Requirements Register'!$E$5:$E$392,"Built & tested") -> 0 | E15: =COUNTIFS('Requirements Register'!$C$5:$C$392,A15,'Requirements Register'!$E$5:$E$392,"Built (manual test)") -> 0 | F15: =COUNTIFS('Requirements Register'!$C$5:$C$392,A15,'Requirements Register'!$E$5:$E$392,"Next") -> 19 | G15: =COUNTIFS('Requirements Register'!$C$5:$C$392,A15,'Requirements Register'!$E$5:$E$392,"Planned") -> 0 | H15: =IF(C15=0,"-",(D15+E15)/C15) -> 0
A16: HLR-12 | B16: =IFERROR(INDEX('Requirements Register'!$D$5:$D$392,MATCH(A16,'Requirements Register'!$A$5:$A$392,0)),"") -> Reward ideas and wishlist: Capture a reward idea in seconds (e.g. a book for Shiragi spotted at the library) without a rule; turn it into a real reward later, or mark it bought or dropped; every reward says who it's for | C16: =COUNTIF('Requirements Register'!$C$5:$C$392,A16) -> 14 | D16: =COUNTIFS('Requirements Register'!$C$5:$C$392,A16,'Requirements Register'!$E$5:$E$392,"Built & tested") -> 0 | E16: =COUNTIFS('Requirements Register'!$C$5:$C$392,A16,'Requirements Register'!$E$5:$E$392,"Built (manual test)") -> 0 | F16: =COUNTIFS('Requirements Register'!$C$5:$C$392,A16,'Requirements Register'!$E$5:$E$392,"Next") -> 14 | G16: =COUNTIFS('Requirements Register'!$C$5:$C$392,A16,'Requirements Register'!$E$5:$E$392,"Planned") -> 0 | H16: =IF(C16=0,"-",(D16+E16)/C16) -> 0
A17: Total | C17: =SUM(C5:C16) -> 153 | D17: =SUM(D5:D16) -> 45 | E17: =SUM(E5:E16) -> 21 | F17: =SUM(F5:F16) -> 77 | G17: =SUM(G5:G16) -> 9 | H17: =IF(C17=0,"-",(D17+E17)/C17) -> 0.43137255

Sheet HLRD 1. Executive summary
A1: 1. Executive summary
A3: Home, career and fun tasks are tracked informally today. Rewards for keeping up are ad hoc, and there's no visibility of consistency. An earlier in-site "Reward Goals" feature existed, but it was goal-centric, tightly coupled to the main site and its Neo4j backend, and not reusable by other clients.
A5: This capstone replaces it with a Rewards microfrontend:
A7: • a React module loaded into the site at runtime;
A8: • a Backend-for-Frontend that serves the web UI, an analytics dashboard and a future Android app;
A9: • integration services (AI photo → task suggestions, reminders) behind resilient adapters.

Sheet HLRD 2. Discovery
A1: 2. Discovery
A3: 2.1 Problem statement
A4: *As a busy working parent, I want to turn the upkeep of each part of my home, career and leisure into small recurring tasks, see my consistency, and reward myself when I keep it up, without the tool becoming another chore.*
A6: 2.2 Personas
A7: Persona | B7: Context | C7: Needs | D7: Frustrations
A8: Mansi, primary user | B8: Working parent; manages household areas (kitchen, laundry, kids' toys), career learning, hobbies | C8: Quick capture on a phone, see what's due, feel progress, self-set treats | D8: Lists get stale; no sense of streaks; motivation fades mid-week
A9: Mansi, reviewer (weekly) | B9: Sunday reflection | C9: Where did effort go? Which streaks are alive? Which rewards are close? | D9: No aggregate view; can't see neglected areas
A10: Capstone evaluator | B10: Assesses architecture | C10: Clear demonstration of MFE, BFF, integration and data-app principles | D10: Monoliths that "claim" microfrontends
A11: Future: family member (out of scope) | B11: Shares household areas | C11: Assigned tasks, own rewards | D11: —
A13: 2.3 Discovery findings
A14: # | B14: Source | C14: Finding | D14: Implication
A15: D1 | B15: Codebase audit (main) | C15: An existing in-site Rewards feature: goals with target days, daily logs, milestones, ₹-valued rewards, 6 fixed categories | D15: Validates the need; its goal model doesn't fit recurring upkeep of physical areas
A16: D2 | B16: Codebase audit | C16: Old feature bundled in the host, dark inline styles, Express + Neo4j API shared with the Weekend Picks backend | D16: Can't deploy, scale or fail independently; heavy infrastructure for simple relational data
A17: D3 | B17: Codebase audit | C17: Passcode gate built but disabled; no auth in practice | D17: Demo-level token is acceptable for MVP; real auth later
A18: D4 | B18: Branch audit | C18: An abandoned Next.js "reward-system" scaffold (React 18) that couldn't be federated into the Vite/React 19 host | D18: Choose Vite-native federation; keep React versions aligned
A19: D5 | B19: User interview (self) | C19: Upkeep is area-based (Kitchen, Wardrobe, Shiragi Toys) not goal-based; frequencies differ (daily vs weekly vs one-off) | D19: Tiles → areas → tasks model with per-task frequency
A20: D6 | B20: User interview | C20: Deciding *what* to do in an area is the hard part | D20: Photo of the area → AI suggests tasks (post-MVP)
A21: D7 | B21: User interview | C21: Tasks are often done and logged later | D21: Backfill completions ("yesterday")
A22: D8 | B22: User interview | C22: Wants weekly insight, not just a to-do list | D22: Separate analytics client (Streamlit)
A23: D9 | B23: Roadmap | C23: An Android app is planned | D23: API-first BFF; mobile-first UI
A24: D11 | B24: PO review of the requirements workbook (2026-09-29) | C24: Preset tiles don't fit everyone's life; the user wants to create, rename, reorder and delete tiles themselves | D24: Tiles become fully user-managed (CRUD); nothing seeded, with an optional one-click starter set (HLR-1)
A25: D12 | B25: PO review (2026-09-29) | C25: When an appliance breaks, the useful information is scattered: customer-care numbers, the last executive who visited, bills, notes (e.g. Bosch dishwasher, Kent water purifier, IFB washing machine, LG fridge, pigeon net, pest control) | D25: Tiles and areas hold notes, contacts and files, grouped by topic (HLR-10)
... A28: D10 | B28: PO review of MVP (2026-09-28) | C28: Rewards float free of the tile/area structure: a reward can be tagged to any task anywhere, so it isn't clear which part of life a reward belongs to | D28: Rewards use the same tiles and areas as tasks, and are matched to tasks inside that scope (HLR-9)
A30: 2.4 Assumptions
A31: • A1. Single user for the MVP; data is personal and low volume (< 1k tasks, < 50k completions).
A32: • A2. The user's calendar is one timezone (Asia/Kolkata by default).
A33: • A3. Rewards are self-fulfilled. There's no purchasing or payment integration.
A34: • A4. The host site remains Vite + React 19 with hash routing.
A36: 2.5 Constraints
A37: • C1. Existing Vercel deployment of the host must keep building (npm run build → dist).
A38: • C2. Solo developer, capstone timeline; prefer managed or zero-ops components.
A39: • C3. AI API keys must never reach the browser.
A40: • C4. Out of scope: Android build, real auth, multi-user, other microfrontends, WhatsApp/Apify/Snowflake integrations.

Sheet HLRD 3. As-Is
A1: 3. As-Is
A3: 3.1 As-Is process
A4: Diagram: see the markdown document or the Miro board.
A6: 3.2 As-Is system
A7: Diagram: see the markdown document or the Miro board.
A9: 3.3 As-Is capabilities and pain points
A10: Area | B10: As-Is | C10: Pain point
A11: Structure | B11: Goals in 6 fixed categories (Food & Kitchen, Health, House, Learning, Creative, Finance) | C11: No notion of physical areas; can't reflect "Kitchen Utility Area" vs "Kitchen"
A12: Frequency | B12: Daily log per goal; target days | C12: Weekly and one-off upkeep doesn't fit
A13: Logging | B13: "Did it today" + duration + note | C13: No backfill; missed logs break streaks unfairly
A14: Rewards | B14: Linked to a goal or milestone day; ₹ value | C14: Can't share one reward across several tasks; no completion-count rule
A15: Insight | B15: Summary cards (active goals, to log today, earned) | C15: No per-area or time-series view
A16: Architecture | B16: Bundled into the host; Neo4j via shared Express API | C16: No independent deploy/failure; not reusable by Android; heavy DB for simple data
A17: Resilience | B17: Single request path; errors surface raw | C17: Rewards failure affects the page
A18: AI | B18: None | C18: Deciding what to do is manual
A19: Service information | B19: Customer-care numbers in phone contacts, executives' numbers in old WhatsApp chats, paper bills in a drawer | C19: When an appliance breaks, finding the last executive or the bill takes longer than the fix

Sheet HLRD 4. To-Be
A1: 4. To-Be
A3: 4.1 To-Be process
A4: Diagram: see the markdown document or the Miro board.
A6: 4.2 To-Be system
A7: Diagram: see the markdown document or the Miro board.
A9: 4.3 Gap analysis (As-Is → To-Be)
A10: # | B10: Capability | C10: As-Is | D10: To-Be | E10: Change type
A11: G1 | B11: Organising model | C11: Goals × 6 categories | D11: 3 tiles × editable areas × tasks | E11: Replace
A12: G2 | B12: Frequency | C12: Daily only | D12: Daily, weekly, one-off | E12: Extend
A13: G3 | B13: Streaks | C13: Daily streak per goal | D13: Per-task streak in days or weeks; current + best; backfill-safe | E13: Replace
A14: G4 | B14: Reward rules | C14: Goal/milestone-bound | D14: Tag to many tasks; *N completions* or *streak of N*; auto-unlock; claim | E14: Replace
A15: G4b | B15: Reward taxonomy | C15: 6 goal categories, separate from anything else | D15: Rewards share the task taxonomy: a tile (required) and optionally one area; tasks and rewards are matched within that scope | E15: New
A16: G5 | B16: Prioritisation | C16: None | D16: High/Med/Low; filter by priority, status, relevance | E16: New
A17: G6 | B17: AI assistance | C17: None | D17: Photo → suggested tasks with human approval | E17: New (post-MVP)
A18: G7 | B18: Insights | C18: 3 summary cards | D18: Dashboard: by tile/area/day, streaks, reward progress, AI acceptance | E18: New
A19: G8 | B19: Delivery | C19: Bundled into host | D19: Independently built and deployed MFE; host fallback | E19: Re-architect
A20: G9 | B20: Backend | C20: Express + Neo4j shared with other features | D20: Dedicated BFF, typed contracts, OpenAPI, relational store | E20: Re-architect
A21: G10 | B21: Clients | C21: Web only | D21: Web, analytics, Android-ready API | E21: New
... A25: G12 | B25: Service records | C25: Scattered across phone contacts, chats and paper | D25: Notes, contacts and files on every tile and area, grouped by topic, with tap-to-call | E25: New
A27: 4.4 Transition plan
A28: Step | B28: Description | C28: Status
A29: T1 | B29: Build the BFF and seed tiles/areas | C29: ✅
A30: T2 | B30: Build the MFE; mount it on #/rewards; remove the old in-site rewards + /rewards Express routes | C30: ✅ (branch)
A31: T3 | B31: Build the Streamlit insights client | C31: ✅
A32: T3a | B32: Schema migrations (Alembic) + export/import, so schema changes never cost existing data | C32: ✅ (branch)
A33: T3b | B33: Reward scope and matching (HLR-9), shipped as the first data-preserving migration | C33: ⏳ next, after T3a
A34: T3c | B34: User-managed tiles (CRUD), no seeding, optional starter set (HLR-1 update) | C34: ⏳ next
A35: T3d | B35: Notes, contacts and files on tiles and areas (HLR-10) | C35: ⏳ next
A36: T3e | B36: Task planning and visibility: milestones, due date/time, days to complete, announce/silent (HLR-11) | C36: ⏳ next
A37: T3f | B37: Reward ideas and wishlist, "For whom" on rewards (HLR-12) | C37: ⏳ next
A38: T4 | B38: Deploy the MFE + BFF; set the host's remote URL; merge to main | C38: ⏳
A39: T5 | B39: Integration services: vision → events/outbox → reminders | C39: ⏳
A40: T6 | B40: Mobile BFF surface; Android client | C40: ⏳ future
A42: No data migration from Neo4j is planned. The old feature held no production data worth carrying over (its auth gate was disabled and the new model differs). Confirm before T4.

Sheet HLRD 5. Scope
A1: 5. Scope
A3: In scope (MVP) | B3: Post-MVP (capstone extensions) | C3: Out of scope
A4: Tile and area CRUD (no seeding, optional starter set), tasks, completions, streaks, rewards, claim; rewards scoped to the same tiles/areas and matched to tasks; notes, contacts and files on tiles and areas | B4: Photo → AI suggestions (vision adapter) | C4: Android app build
A5: React MFE + host integration | B5: Domain events + outbox; reminders (push/email) | C5: Real auth / multi-user
A6: FastAPI BFF with per-client shapes | B6: Calendar ICS feed; object storage; AI weekly coach | C6: Other microfrontends
A7: Streamlit insights | B7: Mobile BFF surface; OIDC | C7: WhatsApp, Apify, Snowflake

Sheet HLRD 6. High-level reqs
A1: 6. High-level requirements
A3: 6.1 Business requirements
A4: ID | B4: Requirement | C4: Success measure
A5: BR-1 | B5: Make recurring upkeep visible and motivating | C5: ≥ 3 active streaks maintained for 2 weeks in personal use
A6: BR-2 | B6: Reduce effort to decide what to do in an area | C6: Post-MVP: ≥ 50 % of AI suggestions marked Relevant
A7: BR-3 | B7: Provide weekly insight into effort distribution | C7: Weekly review done from the dashboard in < 2 min
A8: BR-4 | B8: Demonstrate MFE, BFF, integration and data-app principles (capstone) | C8: 3-minute demo script runs end to end
A9: BR-5 | B9: Be ready for an Android client without backend rewrite | C9: All user actions available via documented API (OpenAPI)
A11: 6.2 High-level functional requirements (epics)
A12: ID | B12: Epic | C12: Summary | D12: Traces to (LLRD) | E12: MVP
A13: HLR-1 | B13: Tiles & areas | C13: User-managed tiles and areas (create, edit, reorder, delete); empty start with an optional starter set | D13: LLR-1.x | E13: 🟡 areas ✅, tiles CRUD ⏳ next
A14: HLR-2 | B14: Task management | C14: Create, prioritise, filter, change status/frequency/relevance | D14: LLR-2.x | E14: ✅
A15: HLR-3 | B15: Completion & streaks | C15: Log completions with note/backfill; activity log; current/best streak | D15: LLR-3.x | E15: ✅
A16: HLR-4 | B16: Rewards | C16: Create, tag, progress, auto-unlock, claim | D16: LLR-4.1–4.8 | E16: ✅
A17: HLR-9 | B17: Reward scope and matching | C17: Rewards live in the same tiles and areas as tasks; tasks are matched to rewards inside that scope (selected tasks, or all tasks in scope); existing rewards migrated without data loss | D17: LLR-4.9–4.18 | E17: ⏳ next
A18: HLR-10 | B18: Notes, contacts and files | C18: Every tile and area holds notes, contacts (customer care, service executives, vendors) and files (bills, warranty cards), grouped by topic such as "Bosch Dishwasher", with tap-to-call and search | D18: LLR-10.x | E18: ⏳ next
A19: HLR-11 | B19: Task planning and visibility | C19: Tasks can be milestones (badge, filter, "milestone completed" reward rule, bigger celebration), have a due date and time and a days-to-complete target, and be announced or silent (silent = hidden from the public view and completed without celebration) | D19: LLR-11.x | E19: ⏳ next
A20: HLR-12 | B20: Reward ideas and wishlist | C20: Capture a reward idea in seconds (e.g. a book for Shiragi spotted at the library) without a rule; turn it into a real reward later, or mark it bought or dropped; every reward says who it's for | D20: LLR-12.x | E20: ⏳ next
A21: HLR-5 | B21: Insights dashboard | C21: Aggregates, filters, cached reads, claim from dashboard | D21: LLR-5.x | E21: ✅
A22: HLR-6 | B22: AI task suggestions | C22: Photos → suggestions → decisions → tasks; non-blocking | D22: LLR-6.x | E22: ⏳
A23: HLR-7 | B23: Module composition | C23: Independently delivered MFE with host fallback | D23: LLR-7.x | E23: ✅
A24: HLR-8 | B24: API (BFF) | C24: Versionable, documented, client-shaped API with demo auth | D24: LLR-8.x | E24: ✅
A26: 6.3 High-level non-functional requirements
A27: ID | B27: Category | C27: Requirement
A28: HNFR-1 | B28: Usability | C28: Mobile-first; every primary action reachable in ≤ 3 taps from the area screen
A29: HNFR-2 | B29: Resilience | C29: No single dependency failure (remote, BFF, AI) blanks the host page
A30: HNFR-3 | B30: Performance | C30: Rewards screen interactive ≤ 2 s on local/broadband; dashboard cached reads
A31: HNFR-4 | B31: Security | C31: Secrets server-side only; CORS allow-list; private photo storage
A32: HNFR-5 | B32: Accessibility | C32: WCAG 2.2 AA intent: labels, focus, live regions, contrast, reduced motion
A33: HNFR-6 | B33: Maintainability | C33: Typed contracts; pure, unit-tested business rules; ≥ 1 test per business rule
A34: HNFR-7 | B34: Portability | C34: HTTP/JSON only between tiers; storage swappable (SQLite → Postgres)

Sheet HLRD 7. Stakeholders and RACI
A1: 7. Stakeholders and RACI
A3: Activity | B3: Mansi (PO/dev) | C3: Capstone evaluator | D3: Future Android dev
A4: Requirements & priorities | B4: A/R | C4: C | D4: I
A5: Architecture & build | B5: A/R | C5: C | D5: C (API)
A6: Demo & evaluation | B6: R | C6: A | D6: —

Sheet HLRD 8. Dependencies
A1: 8. Dependencies
A3: Vercel (host + MFE hosting); a Python host for the BFF (post-MVP deploy); the Anthropic API (post-MVP vision); @originjs/vite-plugin-federation; Streamlit.

Sheet HLRD 9. Risks
A1: 9. Risks
A3: Risk | B3: Likelihood | C3: Impact | D3: Mitigation
A4: Remote not deployed when merged → #/rewards shows fallback | B4: M | C4: M | D4: Deploy the MFE + BFF before merging to main (T4)
A5: AI suggestions low quality | B5: M | C5: L | D5: Human approval per suggestion; acceptance-rate metric in the dashboard
A6: Scope creep into other modules | B6: M | C6: M | D6: Capstone limited to Rewards; roadmap items gated by priority
A7: Contacts and bills visible in the public read-only view (PO decision Q17): executives' personal numbers and your bills exposed once hosted | B7: M | C7: H | D7: Acceptable locally; revisit before going public (option: hide details from visitors while keeping rewards public)
A8: Silent tasks leaking through counts or reward lists in the public view | B8: M | C8: M | D8: Silent tasks and their completions are removed from every response served without the passcode, including counts, dashboard aggregates and reward task lists (BR-R23); tested explicitly
A9: Deleting a tile removes everything under it | B9: L | C9: H | D9: Typed-name confirmation listing what will go, plus an automatic database snapshot first (BR-R18)
A10: React version drift host ↔ remote | B10: L | C10: H | D10: Shared singleton; pinned versions; smoke check

Sheet HLRD 10. Acceptance (MVP)
A1: 10. Acceptance (MVP)
A3: The MVP is accepted when the demo runs without manual workarounds:
A5: • Open #/rewards → Household → Kitchen.
A6: • Add a task.
A7: • Complete it (yesterday + today) → streak 2.
A8: • Tag a *3 completions* reward → complete again → unlock toast → claim.
A9: • The Streamlit dashboard reflects completions, streaks and the claim.
A10: • With the remote or BFF stopped, the site shows the documented fallbacks.
A11: • (HLR-9) Kitchen shows "Rewards you can earn here" for rewards scoped to Household or Household › Kitchen, and the Kitchen task can only be tagged to those.
A12: • (HLR-1) On a fresh database, create a tile "Home", rename it, add areas; "Add suggested tiles" adds the starter set without duplicating "Home".
A13: • (HLR-10) Kitchen › Notes & contacts shows a "Bosch Dishwasher" topic with its customer-care number, past executives with visit dates, bills and notes; tapping a number starts a call on the phone. Household (tile level) holds "Pest Control" with its last executive.
A14: • (HLR-11) A milestone task "Finish React course" (due 31 Oct 2026, 18:00; 30 days to complete) shows its 🏁 badge and due chip; a reward with the rule "milestone completed" unlocks when it's done, with the milestone celebration. A silent task doesn't appear in the read-only view and completes without a toast.
A15: • (HLR-12) At the library, capture the idea "101 Hilarious Jokes" for Shiragi with a cover photo in two taps; later turn it into a reward that unlocks when Shiragi's "Read 20 minutes" task reaches a 7-day streak. The idea stays hidden from the read-only view until then.

Sheet LLRD 1. Detailed discovery
A1: 1. Detailed discovery
A3: 1.1 Discovery questions and answers
A4: # | B4: Question | C4: Answer / decision | D4: Source
A5: Q1 | B5: Which tiles exist and are they editable? | C5: 3 fixed tiles; only areas editable (closed) Superseded by Q15: tiles are fully user-managed | D5: Brief, revised 2026-09-29
A6: Q2 | B6: Household starter list (originally the seed list; now the optional starter set, LLR-1.8)? | C6: Kitchen, Kitchen Utility Area, Laundry, Master Bathroom, Guest Bathroom, Master Bedroom, Guest Room, Hall, Balcony, Books, Makeup, Wardrobe, Shiragi Toys (13). "Kitchen Utility" dropped as a duplicate | D6: PO decision, 2026-09-28
A7: Q3 | B7: What counts as a streak for weekly tasks? | C7: Consecutive Monday–Sunday weeks with ≥ 1 completion | D7: Design decision
A8: Q4 | B8: When does a streak break? | C8: Only after a whole period is missed (done yesterday but not yet today = still alive) | D8: Design decision
A9: Q5 | B9: How can the demo show a streak going up in minutes? | C9: Backfill: log a completion for yesterday or the day before | D9: PO accepted
A10: Q6 | B10: Do completions before a reward existed count? | C10: Yes, all completions of tagged tasks count | D10: Design decision (demo flow)
A11: Q7 | B11: Can an unlocked reward re-lock if a streak breaks? | C11: No, unlock is permanent | D11: Design decision
A12: Q8 | B12: What happens to the old in-site rewards? | C12: Replaced on #/rewards; old UI and Express/Neo4j routes removed | D12: PO decision
A13: Q9 | B13: Timezone? | C13: User-local calendar, default Asia/Kolkata (configurable) | D13: Design decision
A14: Q10 | B14: AI in MVP? | C14: No, post-MVP; the dashboard shows an empty state until then | D14: PO decision
A15: Q11 | B15: Should rewards use the same categories as tasks? | C15: Yes. A reward belongs to a tile (required) and optionally one area of that tile, the same taxonomy as tasks. This is the reward's *scope*, and tasks are matched to rewards within it | D15: PO decision, 2026-09-28
... A29: Q25 | B29: Who can a reward be for? | C29: Any person, as a free-text For whom label with suggestions from earlier entries (default "Me"). It's a label only; all editing stays with the owner | D29: PO decision, 2026-09-29
A31: 1.2 Open items
A32: # | B32: Item | C32: Owner | D32: Needed by
A33: O1 | B33: Hosting choice (closed) Closed by Q13 | C33: PO | D33: —
A34: O5 | B34: Can one reward ever span two tiles (e.g. a treat for Career + Fun)? Current rule: no; create one reward per tile. Revisit if it comes up in real use | C34: PO | D34: Before HLR-9 build
A35: O7 | B35: A *milestone completed* reward with several milestone tasks: unlock when all are done (current rule, BR-R25) or when any is done? | C35: PO | D35: Before HLR-11 build
A36: O8 | B36: Should new tasks default to *Silent* instead of *Announced* once the site is public? | C36: PO | D36: Before going live
A37: O2 | B37: Confirm no data needs migrating from the old Neo4j rewards | C37: PO | D37: Before merging to main
A38: O3 | B38: Reminder channel for the web (push vs email) | C38: PO | D38: Integration phase
A39: O4 | B39: Claude model and per-request cost budget for vision | C39: PO | D39: Phase 4

Sheet LLRD 2. As-Is to To-Be
A1: 2. Feature-level As-Is → To-Be
A3: Feature | B3: As-Is (old in-site rewards) | C3: To-Be (Rewards MFE) | D3: LLR
A4: Navigation | B4: Goals / Rewards tabs, modal-heavy | C4: Tiles → Areas → Area → Task; Rewards tab; deep links #/rewards/... | D4: LLR-1, LLR-7
A5: Categories | B5: 6 fixed + custom categories for goals | C5: User-managed tiles and areas (create, edit, reorder, delete); empty start with an optional starter set | D5: LLR-1.x
A6: Service records | B6: None (phone contacts, chats, paper bills) | C6: Notes, contacts and files on every tile and area, grouped by topic, tap-to-call, search | D6: LLR-10.x
A7: Unit of work | B7: Goal (title, description, type, target days) | C7: Task (title, notes, priority, frequency, status, relevance, source) | D7: LLR-2.x
A8: Logging | B8: "Log today": did it?, duration, note | C8: Complete now or backfill 1–2 days; note | D8: LLR-3.x
A9: Streak | B9: Daily streak per goal | C9: Per task, daily or weekly periods; current + best | D9: LLR-3.x
A10: Milestones | B10: Day-number milestones per goal | C10: Any task can be a milestone: 🏁 badge and filter, a *milestone completed* reward rule, a bigger celebration (plus *streak of N* for day counts) | D10: LLR-11.1–11.4
A11: Deadlines and privacy | B11: Target days per goal; everything visible | C11: Optional due date and time, days to complete (independent); announce or silent per task | D11: LLR-11.5–11.12
A12: Rewards | B12: Per goal/milestone, ₹ value, claim → receive | C12: Many-to-many with tasks; completions or streak rule; auto-unlock; claim | D12: LLR-4.1–4.8
A13: Reward ideas | B13: Rewards defined only together with a goal | C13: Capture an idea first (title, photo, link, where seen, for whom), turn it into a reward later or close it as bought/dropped | D13: LLR-12.x
A14: Reward scope | B14: Reward inherits its goal's category (6 goal categories) | C14: Reward has its own tile + optional area from the same taxonomy as tasks; tasks matched by scope (selected, or all in scope) | D14: LLR-4.9–4.18
... A18: Backend | B18: Express + Neo4j (/api/rewards) | C18: FastAPI BFF + SQLite | D18: LLR-8.x

Sheet LLRD 3. Functional reqs
A1: 3. Detailed functional requirements
A3: LLR-1 Tiles and areas (HLR-1)
A4: ID | B4: Requirement | C4: Status
A5: LLR-1.1 | B5: Superseded by LLR-1.7 (Q15). Was: on first start the system seeds tiles and areas per Q2 | C5: ✅ (to be replaced)
A6: LLR-1.2 | B6: The tiles screen shows each tile's icon, name, area count and active task count | C6: 🟡
A7: LLR-1.3 | B7: The user can add an area to a tile. The name is 1–80 characters, trimmed, and unique within the tile ignoring case | C7: ✅
A8: LLR-1.4 | B8: The user can rename an area under the same rules as LLR-1.3 | C8: ✅
A9: LLR-1.5 | B9: The user can delete an area after confirmation. Its tasks, completions, photos and suggestions are removed with it | C9: ✅
A10: LLR-1.6 | B10: The confirmation text states how many active tasks will be deleted | C10: 🟡
A12: User-managed tiles (HLR-1 update) ⏳ next
A13: ID | B13: Requirement | C13: Status
A14: LLR-1.7 | B14: A new database starts with no tiles. The tiles screen shows "Create your first tile" and an optional Add suggested tiles button. Nothing is seeded automatically | C14: ⏳ next
A15: LLR-1.8 | B15: Add suggested tiles adds the starter set (Career/Office/Work with Learning and Projects; Household with the 13 areas in Q2; Fun with Hobbies and Outings). It only adds tiles and areas whose names don't already exist, so it never duplicates or overwrites anything and can be pressed again safely | C15: ⏳ next
A16: LLR-1.9 | B16: Create a tile: name 1–40 characters, trimmed, unique ignoring case (409 on duplicate); icon (one emoji, optional, default 📁). New tiles go to the end | C16: ⏳ next
A17: LLR-1.10 | B17: Edit a tile: change its name (same rules) and icon. Areas, tasks, rewards and links keep working, because they refer to the tile's id, not its name | C17: ⏳ next
A18: LLR-1.11 | B18: Reorder tiles, and areas within a tile (move up/down; drag on wider screens). The order is saved and used everywhere, including the dashboard | C18: ⏳ next
A19: LLR-1.12 | B19: Delete a tile: the confirmation lists what will be removed (areas, tasks, completions, rewards scoped to it, notes, contacts, files) and requires typing the tile's name. A database snapshot is taken first (BR-R18) | C19: ⏳ next
A20: LLR-1.13 | B20: Existing databases keep their current tiles and areas when this ships: the upgrade removes nothing. They become ordinary user-managed tiles that can be edited or deleted | C20: ⏳ next
A22: AC-1.7 to 1.12
A23: • *Given* a fresh database *when* the Rewards screen opens *then* it shows "Create your first tile" and no tiles.
A24: • *Given* a tile "Home" exists *when* the user presses "Add suggested tiles" *then* Career/Office/Work, Household and Fun are added, "Home" is untouched, and pressing it again adds nothing.
A25: • *Given* a tile "Household" exists *when* the user creates "household" *then* it's rejected: "'household' already exists" (409).
A26: • *Given* "Household" is renamed to "Home and family" *then* its areas, tasks and rewards are unchanged and deep links still open it.
A27: • *Given* the user deletes "Fun" and types "Fun" to confirm *then* Fun, its areas, tasks, completions, scoped rewards and details are removed, and a snapshot exists in data/backups/.
A29: AC-1.3
A30: • *Given* Fun contains "Hobbies" *when* the user adds "hobbies" *then* it's rejected with "'hobbies' already exists in this category" (409) and nothing is created.
A31: • *Given* an empty name *when* submitted *then* the Add button is disabled and the API rejects it (422).
A33: AC-1.5
A34: • *Given* an area with 2 tasks *when* it's deleted and confirmed *then* the area and both tasks return 404 afterwards.
A36: LLR-2 Task management (HLR-2)
A37: ID | B37: Requirement | C37: Status
A38: LLR-2.1 | B38: Create a task with title (1–200 characters, required), notes (≤ 2000), priority (high/medium/low, default medium) and frequency (daily/weekly/one_off, default weekly). Source = manual; status = active; relevance = relevant | C38: ✅
A39: LLR-2.2 | B39: After creating a task, the form keeps the chosen priority and frequency for the next entry and clears the title and notes | C39: 🟡
A40: LLR-2.3 | B40: An area's task list is sorted by priority (high → low), then by creation time | C40: ✅
A41: LLR-2.4 | B41: Filter by priority, status and relevance, singly or combined. The default view is status = active | C41: ✅
A42: LLR-2.5 | B42: Reprioritise from the list (inline select) or from task detail | C42: ✅
A43: LLR-2.6 | B43: Change frequency, status (active/done/archived) and relevance from task detail | C43: ✅
A44: LLR-2.7 | B44: An empty list says "No tasks yet" with the default filter and "No tasks match these filters" otherwise | C44: 🟡
A45: LLR-2.8 | B45: Null values in updates are rejected (422); unknown enum values are rejected (422) | C45: ✅
A46: LLR-2.9 | B46: A cross-area list of active tasks, grouped by area, is available for the reward task picker | C46: ✅
...

Sheet LLRD 4. Screen reqs
A1: 4. Screen requirements (MFE)
A3: Screen | B3: Must show | C3: States | D3: Primary actions
A4: Tiles | B4: Tiles: icon, name, area count, active task count; ⏳ "+ New tile"; ⏳ search box (LLR-10.9) | C4: loading, error+retry; ⏳ empty: "Create your first tile" + "Add suggested tiles" | D4: open tile; ⏳ create, edit, reorder, delete tile
A5: Tile (category) | B5: Breadcrumb; areas with active count; ⏳ tabs *Areas* / *Notes & contacts* | C5: loading, error, empty ("No areas yet"), not found | D5: add, rename (inline), delete (confirm) area; ⏳ edit or delete this tile; ⏳ tile-level notes, contacts, files
A6: ⏳ Notes & contacts (tab on tile and area) | B6: Topic groups ("General" last); per topic: last executive, contacts (role, organisation, phones with Call / WhatsApp / Copy), files (thumbnail or PDF icon, date, amount), notes | C6: loading, error, empty ("No notes or contacts yet"), read-only (no edit controls) | D6: add note, contact, file; edit, delete, change topic
A7: Area | B7: Breadcrumb; active count; add form (⏳ with More options: milestone, announce/silent, due date and time, days to complete); filters (collapsible; ⏳ milestones, overdue/due today/this week, sort by due); task rows (title, frequency, source, status, streak 🔥, priority select, ✓; ⏳ 🏁 milestone, due chip, 🔕 silent); ⏳ "Rewards you can earn here" (matching rewards with progress) | C7: loading, error, "No tasks yet" / "No tasks match these filters"; ⏳ "No rewards for this area yet" + create link prefilled with this scope | D7: add task, filter, reprioritise, quick complete, open task; ⏳ create reward for this area
A8: Task | B8: Breadcrumb; stats (current, best, completions); log completion (when + note); matching rewards (tagged, or ⏳ "Counts automatically") + tag select limited to in-scope rewards; settings chips; activity log | C8: loading, error, "No completions yet", inactive-task notice | D8: complete, tag reward, change settings
A9: Rewards | B9: Status filter (⏳ plus *Ideas* and *Closed*); ⏳ for-whom filter; ⏳ "+ Idea" quick capture; ⏳ idea cards (photo, title, for whom, where seen, *Turn into reward*, *Bought*, *Dropped*); ⏳ tile and area filters; create form (⏳ tile → area → match mode, then task picker limited to scope, grouped by area); cards: image, title, ⏳ scope breadcrumb + match mode, status, rule, progress, tags | C9: loading, error, empty per filter; ⏳ *Needs a tile* badge | D9: create, claim, edit tasks, ⏳ change scope (locked only)
A11: Touch and accessibility: controls ≥ 44 px high (chips ≥ 36 px), inputs 16 px, labelled controls, role="radiogroup" chips, aria-live toasts, focus ring visible, reduced-motion respected.

Sheet LLRD 5. User-facing messages
A1: 5. User-facing messages
A3: Code / situation | B3: Message
A4: BFF unreachable | B4: "Can't reach the rewards service. Is the BFF running?"
A5: Remote unavailable (host) | B5: "Rewards is unavailable right now. The rewards module couldn't be loaded. The rest of the site still works."
A6: Duplicate area | B6: "'<name>' already exists in this category"
A7: Complete inactive task | B7: "Only active tasks can be completed (this one is <status>)"
A8: Future completion | B8: "completedAt cannot be in the future"
A9: Claim locked reward | B9: "This reward is still locked"
A10: Unknown tagged tasks | B10: "Unknown task ids: [..]"
A11: Unlock | B11: "🎉 Reward unlocked: <title>"
A12: ⏳ Duplicate tile | B12: "'<name>' already exists"
A13: ⏳ Delete tile | B13: "Delete <tile>? This removes <n> areas, <n> tasks, <n> completions, <n> rewards and <n> notes, contacts and files. A backup is saved first. Type <tile> to confirm."
A14: ⏳ Starter set | B14: "Added <n> tiles and <n> areas" / "You already have all the suggested tiles"
... A29: ⏳ AI fallback | B29: "AI suggestions unavailable, add tasks manually"

Sheet LLRD 6. Non-functional reqs
A1: 6. Detailed non-functional requirements
A3: ID | B3: Requirement | C3: Verification
A4: NFR-D1 | B4: Remote exposed chunk ≤ 50 KB gzip (now ~11 KB) | C4: build output
A5: NFR-D2 | B5: Remote load after navigating to #/rewards ≤ 500 ms locally (measured ~36 ms client-side nav, ~275 ms cold) | C5: Resource Timing
A6: NFR-D3 | B6: Dashboard issues ≤ 1 BFF read per window per 30 s | C6: st.cache_data TTL
A7: NFR-D4 | B7: No horizontal scroll at 375 px width | C7: measured scrollWidth = viewport
A8: NFR-D5 | B8: Stats for N tasks use one activity query (no N+1) | C8: code review (task_stats)
A9: NFR-D6 | B9: Every business rule BR-R1…R30 has ≥ 1 automated test | C9: traceability §7
A10: NFR-D8 | B10: No schema change may delete or rewrite existing rows except as specified (LLR-4.18); every migration has an upgrade test run against a copy of a pre-migration database | C10: migration tests
A11: NFR-D9 | B11: Uploaded files are stored outside any public web folder with random names, served only through the BFF, and count against a 2 GB soft limit on the droplet (warning shown); moving to object storage later changes no requirement | C11: code review, upload tests
A12: NFR-D10 | B12: Search over notes, contacts and files returns in ≤ 300 ms for 5,000 items | C12: test with generated data
A13: NFR-D11 | B13: Every read endpoint has a test that a silent task leaves no trace (item, count or aggregate) in its response without the passcode | C13: privacy tests
A14: NFR-D7 | B14: Naive datetimes never reach storage | C14: UTCDateTime raises

Sheet LLRD 7. Traceability matrix
A1: 7. Traceability matrix
A3: LLR | B3: Endpoint(s) | C3: Automated test(s)
A4: LLR-1.1 (superseded) | B4: lifespan seed, GET /categories | C4: test_seeded_tiles_and_sub_tiles (to be replaced by the LLR-1.7 tests)
A5: LLR-1.3–1.5 | B5: POST/PATCH/DELETE /areas | C5: test_area_add_rename_delete
A6: LLR-1.7–1.13; BR-R17–R19; LLR-8.10 | B6: /categories* | C6: ⏳ planned: test_fresh_database_has_no_tiles, test_starter_set_is_idempotent, test_tile_crud_and_unique_names, test_delete_tile_snapshots_and_cascades, test_upgrade_keeps_existing_tiles
A7: LLR-12.1–12.9; BR-R27–R30; LLR-8.13 | B7: /rewards* | C7: ⏳ planned: test_idea_needs_only_title, test_idea_never_unlocks_or_counts, test_activate_idea_keeps_details_and_evaluates, test_close_and_reopen_idea, test_ideas_silent_by_default, test_filter_by_for_whom, test_migration_defaults_existing_rewards
A8: LLR-11.1–11.13; BR-R22–R26; LLR-8.12 | B8: tasks, rewards, /dashboard/summary | C8: ⏳ planned: test_task_planning_fields_round_trip, test_overdue_rules, test_milestone_reward_needs_all_milestones, test_silent_tasks_invisible_without_passcode, test_silent_completion_has_no_celebration_flag, test_migration_defaults_existing_tasks
A9: LLR-10.1–10.12; BR-R20–R21; LLR-8.11 | B9: details, files, /search | C9: ⏳ planned: test_details_grouped_by_topic, test_last_executive_is_latest_visit, test_file_upload_rules, test_search_matches_phone_digits, test_read_only_view_shows_details_but_blocks_edits
A10: LLR-2.1, 2.3–2.5, 2.8, 2.9 | B10: POST /areas/{id}/tasks, GET /areas/{id}/tasks, PATCH /tasks/{id}, GET /tasks | C10: test_create_filter_and_reprioritise_tasks
A11: LLR-3.1, 3.6, 3.7; BR-R2–R4 | B11: POST /tasks/{id}/complete, GET /tasks/{id}/activity, GET /tasks/{id} | C11: test_completions_build_streak_and_activity_log, test_daily_streak, test_weekly_streak
A12: LLR-3.3–3.5; BR-R4, R5 | B12: POST /tasks/{id}/complete | C12: test_completion_rules, test_one_off_streak_is_done_or_not
A13: LLR-4.1, 4.2, 4.6, 4.7; BR-R7, R9, R10 | B13: /rewards* | C13: test_reward_unlocks_on_completion_count_then_claim, test_reward_already_met_unlocks_on_create_and_rejects_unknown_tasks, test_completions_rule_progress
A14: BR-R8 | B14: /rewards* | C14: test_streak_reward_uses_best_current_streak_across_tasks, test_streak_rule_progress
... A25: LLR-4.18; BR-R16 | B25: migration 0002_reward_scope | C25: ⏳ planned: test_migration_infers_scope_and_keeps_data (runs against a pre-migration fixture database)
